"rectype","issueid","project_owner","project_name","actor","time","text","action","title"
"issue_title","999","nilearn","nilearn","arthurmensch","2016-02-19 14:45:28","Simple Python 3 glitch:

```
Traceback (most recent call last):
  File ""/home/arthur/work/repos/nilearn/examples/02_decoding/plot_mixed_gambles_space_net.py"", line 16, in <module>
    data = fetch_mixed_gambles(n_subjects=16)
  File ""/home/arthur/work/repos/nilearn/nilearn/datasets/func.py"", line 1285, in fetch_mixed_gambles
    X, y, mask_img = _load_mixed_gambles(map(nibabel.load, data.zmaps))
  File ""/home/arthur/work/repos/nilearn/nilearn/datasets/func.py"", line 1209, in _load_mixed_gambles
    mask = np.sum(mask, axis=0) > .5 * len(zmap_imgs)
TypeError: object of type 'map' has no len()
```
","start issue","plot_mixed_gambles_space_net if broken on Python 3"
"issue_closed","999","nilearn","nilearn","AlexandreAbraham","2016-03-03 09:06:45","","closed issue","plot_mixed_gambles_space_net if broken on Python 3"
"issue_comment","999","nilearn","nilearn","AlexandreAbraham","2016-02-19 14:46:42","This is surprising. These examples are run routinely in CircleCI without problems.
","",""
"issue_comment","999","nilearn","nilearn","arthurmensch","2016-02-19 14:46:58","With Python 3 ? No chance given the error...
","",""
"issue_comment","999","nilearn","nilearn","AlexandreAbraham","2016-02-19 14:51:07","OK, CircleCI runs on Python 2. Oooooooold!
","",""
