"rectype","issueid","project_owner","project_name","actor","time","text","action","title"
"issue_title","473","pycqa","astroid","KyrychukD","2017-12-20 11:18:44","Traceback indicates that this is probably an issue with astroid. Please let me know if I should address this issue to pylint bug tracker instead.

### Steps to reproduce
1. `pylint example.py`

### `pip freeze`

```
astroid==1.6.0
isort==4.2.15
lazy-object-proxy==1.3.1
mccabe==0.6.1
pylint==1.8.1
six==1.11.0
wrapt==1.10.11
```


### `example.py`

```python
class Class:
    @classmethod
    def class_method(cls):
        _ = cls.__init__.__annotations__
```

### Current behavior
Pylint fails with the following error:

```
Traceback (most recent call last):
  File ""/home/dmytro/.virtualenvs/tmp-e8ba418cce8a54b3/bin/pylint"", line 11, in <module>
    sys.exit(run_pylint())
  File ""/home/dmytro/.virtualenvs/tmp-e8ba418cce8a54b3/lib/python3.6/site-packages/pylint/__init__.py"", line 16, in run_pylint
    Run(sys.argv[1:])
  File ""/home/dmytro/.virtualenvs/tmp-e8ba418cce8a54b3/lib/python3.6/site-packages/pylint/lint.py"", line 1347, in __init__
    linter.check(args)
  File ""/home/dmytro/.virtualenvs/tmp-e8ba418cce8a54b3/lib/python3.6/site-packages/pylint/lint.py"", line 768, in check
    self._do_check(files_or_modules)
  File ""/home/dmytro/.virtualenvs/tmp-e8ba418cce8a54b3/lib/python3.6/site-packages/pylint/lint.py"", line 901, in _do_check
    self.check_astroid_module(ast_node, walker, rawcheckers, tokencheckers)
  File ""/home/dmytro/.virtualenvs/tmp-e8ba418cce8a54b3/lib/python3.6/site-packages/pylint/lint.py"", line 980, in check_astroid_module
    walker.walk(ast_node)
  File ""/home/dmytro/.virtualenvs/tmp-e8ba418cce8a54b3/lib/python3.6/site-packages/pylint/utils.py"", line 1014, in walk
    self.walk(child)
  File ""/home/dmytro/.virtualenvs/tmp-e8ba418cce8a54b3/lib/python3.6/site-packages/pylint/utils.py"", line 1014, in walk
    self.walk(child)
  File ""/home/dmytro/.virtualenvs/tmp-e8ba418cce8a54b3/lib/python3.6/site-packages/pylint/utils.py"", line 1014, in walk
    self.walk(child)
  File ""/home/dmytro/.virtualenvs/tmp-e8ba418cce8a54b3/lib/python3.6/site-packages/pylint/utils.py"", line 1011, in walk
    cb(astroid)
  File ""/home/dmytro/.virtualenvs/tmp-e8ba418cce8a54b3/lib/python3.6/site-packages/pylint/checkers/typecheck.py"", line 714, in visit_attribute
    if not [n for n in owner.getattr(node.attrname)
  File ""/home/dmytro/.virtualenvs/tmp-e8ba418cce8a54b3/lib/python3.6/site-packages/astroid/bases.py"", line 298, in getattr
    return self._proxied.getattr(name, context)
  File ""/home/dmytro/.virtualenvs/tmp-e8ba418cce8a54b3/lib/python3.6/site-packages/astroid/scoped_nodes.py"", line 1438, in getattr
    return [self.special_attributes.lookup(name)]
  File ""/home/dmytro/.virtualenvs/tmp-e8ba418cce8a54b3/lib/python3.6/site-packages/astroid/interpreter/objectmodel.py"", line 110, in lookup
    return getattr(self, ""py"" + name)
  File ""/home/dmytro/.virtualenvs/tmp-e8ba418cce8a54b3/lib/python3.6/site-packages/astroid/interpreter/objectmodel.py"", line 237, in py__annotations__
    six.moves.zip(args.args, args.annotations),
TypeError: zip argument #1 must support iteration
```

### Expected behavior
Pylint is not failing.

### ``python -c ""from astroid import __pkginfo__; print(__pkginfo__.version)""`` output
1.6.0


### Notes

The error is reproducible on the current master version of astroid.

The error is not reproducible when accessing `__annotations__` outside of `@classmethod`. The error is not reproducible when accessing `__annotations__` of non-magic method (`_ = cls.some_method.__annotations__` even within `@classmethod` would not crash pylint).","start issue","TypeError when accessing magic method's annotations form @classmethod"
"issue_closed","473","pycqa","astroid","PCManticore","2017-12-27 13:55:46","","closed issue","TypeError when accessing magic method's annotations form @classmethod"
